<?xml version='1.0'?>
<sdf version='1.7'>
  <model name='elRoboto'>
    <link name='base_link'>
      <pose>0 0 0 0 -0 0</pose>
      <inertial>
        <pose>-5e-06 0.054174 0.038824 0 -0 0</pose>
        <mass>0.7102</mass>
        <inertia>
          <ixx>0.0039943</ixx>
          <ixy>3.697e-07</ixy>
          <ixz>-5.7364e-08</ixz>
          <iyy>0.0014946</iyy>
          <iyz>-0.00036051</iyz>
          <izz>0.0042554</izz>
        </inertia>
      </inertial>
      <self_collide>0</self_collide>
      <enable_wind>0</enable_wind>
      <kinematic>0</kinematic>
      <visual name='base_link_visual'>
        <pose>0 0 0 0 -0 0</pose>
        <geometry>
          <mesh>
            <scale>1 1 1</scale>
            <uri>file:///home/todosi/ar4_ros_driver/install/ar_description/share/ar_description/meshes/ar4/base_link.STL</uri>
          </mesh>
        </geometry>
        <material>
          <shader type='pixel'/>
        </material>
        <transparency>0</transparency>
        <cast_shadows>1</cast_shadows>
      </visual>
      <collision name='base_link_collision'>
        <laser_retro>0</laser_retro>
        <max_contacts>10</max_contacts>
        <pose>0 0 0 0 -0 0</pose>
        <geometry>
          <mesh>
            <uri>/home/todosi/ar4_ros_driver/install/ar_description/share/ar_description/meshes/ar4/base_link.STL</uri>
            <scale>1 1 1</scale>
          </mesh>
        </geometry>
        <surface>
          <friction>
            <ode>
              <mu>1</mu>
              <mu2>1</mu2>
              <fdir1>0 0 0</fdir1>
              <slip1>0</slip1>
              <slip2>0</slip2>
            </ode>
            <torsional>
              <coefficient>1</coefficient>
              <patch_radius>0</patch_radius>
              <surface_radius>0</surface_radius>
              <use_patch_radius>1</use_patch_radius>
              <ode>
                <slip>0</slip>
              </ode>
            </torsional>
          </friction>
          <bounce>
            <restitution_coefficient>0</restitution_coefficient>
            <threshold>1e+06</threshold>
          </bounce>
          <contact>
            <collide_without_contact>0</collide_without_contact>
            <collide_without_contact_bitmask>1</collide_without_contact_bitmask>
            <collide_bitmask>1</collide_bitmask>
            <ode>
              <soft_cfm>0</soft_cfm>
              <soft_erp>0.2</soft_erp>
              <kp>1e+13</kp>
              <kd>1</kd>
              <max_vel>0.01</max_vel>
              <min_depth>0</min_depth>
            </ode>
            <bullet>
              <split_impulse>1</split_impulse>
              <split_impulse_penetration_threshold>-0.01</split_impulse_penetration_threshold>
              <soft_cfm>0</soft_cfm>
              <soft_erp>0.2</soft_erp>
              <kp>1e+13</kp>
              <kd>1</kd>
            </bullet>
          </contact>
        </surface>
      </collision>
    </link>
    <link name='gripper_jaw1_link'>
      <pose>-0.006999 -0.359079 0.474771 -3.14159 3e-06 -3.14159</pose>
      <inertial>
        <pose>-0.004358 -0.004695 0.007571 0 -0 0</pose>
        <mass>0.01</mass>
        <inertia>
          <ixx>1.23e-06</ixx>
          <ixy>-4e-08</ixy>
          <ixz>1.2e-07</ixz>
          <iyy>1.15e-06</iyy>
          <iyz>1.6e-07</iyz>
          <izz>1.02e-06</izz>
        </inertia>
      </inertial>
      <self_collide>0</self_collide>
      <enable_wind>0</enable_wind>
      <kinematic>0</kinematic>
      <visual name='gripper_jaw1_link_visual'>
        <pose>0 0 0 0 -0 0</pose>
        <geometry>
          <mesh>
            <scale>1 1 1</scale>
            <uri>file:///home/todosi/ar4_ros_driver/install/ar_description/share/ar_description/meshes/ar4_gripper/gripper_jaw1_link.stl</uri>
          </mesh>
        </geometry>
        <material>
          <shader type='pixel'/>
        </material>
        <transparency>0</transparency>
        <cast_shadows>1</cast_shadows>
      </visual>
      <collision name='gripper_jaw1_link_collision'>
        <laser_retro>0</laser_retro>
        <max_contacts>10</max_contacts>
        <pose>0 0 0 0 -0 0</pose>
        <geometry>
          <mesh>
            <uri>/home/todosi/ar4_ros_driver/install/ar_description/share/ar_description/meshes/ar4_gripper/gripper_jaw1_link.stl</uri>
            <scale>1 1 1</scale>
          </mesh>
        </geometry>
        <surface>
          <friction>
            <ode>
              <mu>1</mu>
              <mu2>1</mu2>
              <fdir1>0 0 0</fdir1>
              <slip1>0</slip1>
              <slip2>0</slip2>
            </ode>
            <torsional>
              <coefficient>1</coefficient>
              <patch_radius>0</patch_radius>
              <surface_radius>0</surface_radius>
              <use_patch_radius>1</use_patch_radius>
              <ode>
                <slip>0</slip>
              </ode>
            </torsional>
          </friction>
          <bounce>
            <restitution_coefficient>0</restitution_coefficient>
            <threshold>1e+06</threshold>
          </bounce>
          <contact>
            <collide_without_contact>0</collide_without_contact>
            <collide_without_contact_bitmask>1</collide_without_contact_bitmask>
            <collide_bitmask>1</collide_bitmask>
            <ode>
              <soft_cfm>0</soft_cfm>
              <soft_erp>0.2</soft_erp>
              <kp>1e+13</kp>
              <kd>1</kd>
              <max_vel>0.01</max_vel>
              <min_depth>0</min_depth>
            </ode>
            <bullet>
              <split_impulse>1</split_impulse>
              <split_impulse_penetration_threshold>-0.01</split_impulse_penetration_threshold>
              <soft_cfm>0</soft_cfm>
              <soft_erp>0.2</soft_erp>
              <kp>1e+13</kp>
              <kd>1</kd>
            </bullet>
          </contact>
        </surface>
      </collision>
    </link>
    <link name='gripper_jaw2_link'>
      <pose>-0.006999 -0.359079 0.474771 2e-06 -0 0</pose>
      <inertial>
        <pose>-0.00424 -0.004912 0.008146 0 -0 0</pose>
        <mass>0.01</mass>
        <inertia>
          <ixx>1.18e-06</ixx>
          <ixy>-4e-08</ixy>
          <ixz>1.3e-07</ixz>
          <iyy>1.1e-06</iyy>
          <iyz>1.3e-07</iyz>
          <izz>1.01e-06</izz>
        </inertia>
      </inertial>
      <self_collide>0</self_collide>
      <enable_wind>0</enable_wind>
      <kinematic>0</kinematic>
      <visual name='gripper_jaw2_link_visual'>
        <pose>0 0 0 0 -0 0</pose>
        <geometry>
          <mesh>
            <scale>1 1 1</scale>
            <uri>file:///home/todosi/ar4_ros_driver/install/ar_description/share/ar_description/meshes/ar4_gripper/gripper_jaw2_link.stl</uri>
          </mesh>
        </geometry>
        <material>
          <shader type='pixel'/>
        </material>
        <transparency>0</transparency>
        <cast_shadows>1</cast_shadows>
      </visual>
      <collision name='gripper_jaw2_link_collision'>
        <laser_retro>0</laser_retro>
        <max_contacts>10</max_contacts>
        <pose>0 0 0 0 -0 0</pose>
        <geometry>
          <mesh>
            <uri>/home/todosi/ar4_ros_driver/install/ar_description/share/ar_description/meshes/ar4_gripper/gripper_jaw2_link.stl</uri>
            <scale>1 1 1</scale>
          </mesh>
        </geometry>
        <surface>
          <friction>
            <ode>
              <mu>1</mu>
              <mu2>1</mu2>
              <fdir1>0 0 0</fdir1>
              <slip1>0</slip1>
              <slip2>0</slip2>
            </ode>
            <torsional>
              <coefficient>1</coefficient>
              <patch_radius>0</patch_radius>
              <surface_radius>0</surface_radius>
              <use_patch_radius>1</use_patch_radius>
              <ode>
                <slip>0</slip>
              </ode>
            </torsional>
          </friction>
          <bounce>
            <restitution_coefficient>0</restitution_coefficient>
            <threshold>1e+06</threshold>
          </bounce>
          <contact>
            <collide_without_contact>0</collide_without_contact>
            <collide_without_contact_bitmask>1</collide_without_contact_bitmask>
            <collide_bitmask>1</collide_bitmask>
            <ode>
              <soft_cfm>0</soft_cfm>
              <soft_erp>0.2</soft_erp>
              <kp>1e+13</kp>
              <kd>1</kd>
              <max_vel>0.01</max_vel>
              <min_depth>0</min_depth>
            </ode>
            <bullet>
              <split_impulse>1</split_impulse>
              <split_impulse_penetration_threshold>-0.01</split_impulse_penetration_threshold>
              <soft_cfm>0</soft_cfm>
              <soft_erp>0.2</soft_erp>
              <kp>1e+13</kp>
              <kd>1</kd>
            </bullet>
          </contact>
        </surface>
      </collision>
    </link>
    <link name='link_1'>
      <pose>0 0 0 3.14159 -0 0</pose>
      <inertial>
        <pose>-0.022706 0.04294 -0.12205 0 -0 0</pose>
        <mass>0.88065</mass>
        <inertia>
          <ixx>0.0034</ixx>
          <ixy>0.00042296</ixy>
          <ixz>-0.00089231</ixz>
          <iyy>0.0041778</iyy>
          <iyz>0.0010848</iyz>
          <izz>0.0027077</izz>
        </inertia>
      </inertial>
      <self_collide>0</self_collide>
      <enable_wind>0</enable_wind>
      <kinematic>0</kinematic>
      <visual name='link_1_visual'>
        <pose>0 0 0 0 -0 0</pose>
        <geometry>
          <mesh>
            <scale>1 1 1</scale>
            <uri>file:///home/todosi/ar4_ros_driver/install/ar_description/share/ar_description/meshes/ar4/link_1.STL</uri>
          </mesh>
        </geometry>
        <material>
          <shader type='pixel'/>
        </material>
        <transparency>0</transparency>
        <cast_shadows>1</cast_shadows>
      </visual>
      <collision name='link_1_collision'>
        <laser_retro>0</laser_retro>
        <max_contacts>10</max_contacts>
        <pose>0 0 0 0 -0 0</pose>
        <geometry>
          <mesh>
            <uri>/home/todosi/ar4_ros_driver/install/ar_description/share/ar_description/meshes/ar4/link_1.STL</uri>
            <scale>1 1 1</scale>
          </mesh>
        </geometry>
        <surface>
          <friction>
            <ode>
              <mu>1</mu>
              <mu2>1</mu2>
              <fdir1>0 0 0</fdir1>
              <slip1>0</slip1>
              <slip2>0</slip2>
            </ode>
            <torsional>
              <coefficient>1</coefficient>
              <patch_radius>0</patch_radius>
              <surface_radius>0</surface_radius>
              <use_patch_radius>1</use_patch_radius>
              <ode>
                <slip>0</slip>
              </ode>
            </torsional>
          </friction>
          <bounce>
            <restitution_coefficient>0</restitution_coefficient>
            <threshold>1e+06</threshold>
          </bounce>
          <contact>
            <collide_without_contact>0</collide_without_contact>
            <collide_without_contact_bitmask>1</collide_without_contact_bitmask>
            <collide_bitmask>1</collide_bitmask>
            <ode>
              <soft_cfm>0</soft_cfm>
              <soft_erp>0.2</soft_erp>
              <kp>1e+13</kp>
              <kd>1</kd>
              <max_vel>0.01</max_vel>
              <min_depth>0</min_depth>
            </ode>
            <bullet>
              <split_impulse>1</split_impulse>
              <split_impulse_penetration_threshold>-0.01</split_impulse_penetration_threshold>
              <soft_cfm>0</soft_cfm>
              <soft_erp>0.2</soft_erp>
              <kp>1e+13</kp>
              <kd>1</kd>
            </bullet>
          </contact>
        </surface>
      </collision>
    </link>
    <link name='link_2'>
      <pose>0 -0.0642 0.16977 -1.57079 3e-06 1.5708</pose>
      <inertial>
        <pose>0.064818 -0.11189 -0.038671 0 -0 0</pose>
        <mass>0.57738</mass>
        <inertia>
          <ixx>0.0047312</ixx>
          <ixy>0.0022624</ixy>
          <ixz>0.00032144</ixz>
          <iyy>0.0020836</iyy>
          <iyz>-0.00056569</iyz>
          <izz>0.0056129</izz>
        </inertia>
      </inertial>
      <self_collide>0</self_collide>
      <enable_wind>0</enable_wind>
      <kinematic>0</kinematic>
      <visual name='link_2_visual'>
        <pose>0 0 0 0 -0 0</pose>
        <geometry>
          <mesh>
            <scale>1 1 1</scale>
            <uri>file:///home/todosi/ar4_ros_driver/install/ar_description/share/ar_description/meshes/ar4/link_2.STL</uri>
          </mesh>
        </geometry>
        <material>
          <shader type='pixel'/>
        </material>
        <transparency>0</transparency>
        <cast_shadows>1</cast_shadows>
      </visual>
      <collision name='link_2_collision'>
        <laser_retro>0</laser_retro>
        <max_contacts>10</max_contacts>
        <pose>0 0 0 0 -0 0</pose>
        <geometry>
          <mesh>
            <uri>/home/todosi/ar4_ros_driver/install/ar_description/share/ar_description/meshes/ar4/link_2.STL</uri>
            <scale>1 1 1</scale>
          </mesh>
        </geometry>
        <surface>
          <friction>
            <ode>
              <mu>1</mu>
              <mu2>1</mu2>
              <fdir1>0 0 0</fdir1>
              <slip1>0</slip1>
              <slip2>0</slip2>
            </ode>
            <torsional>
              <coefficient>1</coefficient>
              <patch_radius>0</patch_radius>
              <surface_radius>0</surface_radius>
              <use_patch_radius>1</use_patch_radius>
              <ode>
                <slip>0</slip>
              </ode>
            </torsional>
          </friction>
          <bounce>
            <restitution_coefficient>0</restitution_coefficient>
            <threshold>1e+06</threshold>
          </bounce>
          <contact>
            <collide_without_contact>0</collide_without_contact>
            <collide_without_contact_bitmask>1</collide_without_contact_bitmask>
            <collide_bitmask>1</collide_bitmask>
            <ode>
              <soft_cfm>0</soft_cfm>
              <soft_erp>0.2</soft_erp>
              <kp>1e+13</kp>
              <kd>1</kd>
              <max_vel>0.01</max_vel>
              <min_depth>0</min_depth>
            </ode>
            <bullet>
              <split_impulse>1</split_impulse>
              <split_impulse_penetration_threshold>-0.01</split_impulse_penetration_threshold>
              <soft_cfm>0</soft_cfm>
              <soft_erp>0.2</soft_erp>
              <kp>1e+13</kp>
              <kd>1</kd>
            </bullet>
          </contact>
        </surface>
      </collision>
    </link>
    <link name='link_3'>
      <pose>-0.006999 -0.064199 0.47477 1.57079 -5e-06 -1.57079</pose>
      <inertial>
        <pose>-0.000298 -0.023661 -0.001913 0 -0 0</pose>
        <mass>0.1787</mass>
        <inertia>
          <ixx>0.0001685</ixx>
          <ixy>-2.7713e-05</ixy>
          <ixz>5.6885e-06</ixz>
          <iyy>0.00012865</iyy>
          <iyz>2.9256e-05</iyz>
          <izz>0.00020744</izz>
        </inertia>
      </inertial>
      <self_collide>0</self_collide>
      <enable_wind>0</enable_wind>
      <kinematic>0</kinematic>
      <visual name='link_3_visual'>
        <pose>0 0 0 0 -0 0</pose>
        <geometry>
          <mesh>
            <scale>1 1 1</scale>
            <uri>file:///home/todosi/ar4_ros_driver/install/ar_description/share/ar_description/meshes/ar4/link_3.STL</uri>
          </mesh>
        </geometry>
        <material>
          <shader type='pixel'/>
        </material>
        <transparency>0</transparency>
        <cast_shadows>1</cast_shadows>
      </visual>
      <collision name='link_3_collision'>
        <laser_retro>0</laser_retro>
        <max_contacts>10</max_contacts>
        <pose>0 0 0 0 -0 0</pose>
        <geometry>
          <mesh>
            <uri>/home/todosi/ar4_ros_driver/install/ar_description/share/ar_description/meshes/ar4/link_3.STL</uri>
            <scale>1 1 1</scale>
          </mesh>
        </geometry>
        <surface>
          <friction>
            <ode>
              <mu>1</mu>
              <mu2>1</mu2>
              <fdir1>0 0 0</fdir1>
              <slip1>0</slip1>
              <slip2>0</slip2>
            </ode>
            <torsional>
              <coefficient>1</coefficient>
              <patch_radius>0</patch_radius>
              <surface_radius>0</surface_radius>
              <use_patch_radius>1</use_patch_radius>
              <ode>
                <slip>0</slip>
              </ode>
            </torsional>
          </friction>
          <bounce>
            <restitution_coefficient>0</restitution_coefficient>
            <threshold>1e+06</threshold>
          </bounce>
          <contact>
            <collide_without_contact>0</collide_without_contact>
            <collide_without_contact_bitmask>1</collide_without_contact_bitmask>
            <collide_bitmask>1</collide_bitmask>
            <ode>
              <soft_cfm>0</soft_cfm>
              <soft_erp>0.2</soft_erp>
              <kp>1e+13</kp>
              <kd>1</kd>
              <max_vel>0.01</max_vel>
              <min_depth>0</min_depth>
            </ode>
            <bullet>
              <split_impulse>1</split_impulse>
              <split_impulse_penetration_threshold>-0.01</split_impulse_penetration_threshold>
              <soft_cfm>0</soft_cfm>
              <soft_erp>0.2</soft_erp>
              <kp>1e+13</kp>
              <kd>1</kd>
            </bullet>
          </contact>
        </surface>
      </collision>
    </link>
    <link name='link_4'>
      <pose>-0.006999 -0.064199 0.47477 1.99564 1.57079 -2.71675</pose>
      <inertial>
        <pose>-0.00168 -0.000573 -0.074404 0 -0 0</pose>
        <mass>0.34936</mass>
        <inertia>
          <ixx>0.0030532</ixx>
          <ixy>-1.8615e-05</ixy>
          <ixz>-7.0047e-05</ixz>
          <iyy>0.0031033</iyy>
          <iyz>-2.3301e-05</iyz>
          <izz>0.00022264</izz>
        </inertia>
      </inertial>
      <self_collide>0</self_collide>
      <enable_wind>0</enable_wind>
      <kinematic>0</kinematic>
      <visual name='link_4_visual'>
        <pose>0 0 0 0 -0 0</pose>
        <geometry>
          <mesh>
            <scale>1 1 1</scale>
            <uri>file:///home/todosi/ar4_ros_driver/install/ar_description/share/ar_description/meshes/ar4/link_4.STL</uri>
          </mesh>
        </geometry>
        <material>
          <shader type='pixel'/>
        </material>
        <transparency>0</transparency>
        <cast_shadows>1</cast_shadows>
      </visual>
      <collision name='link_4_collision'>
        <laser_retro>0</laser_retro>
        <max_contacts>10</max_contacts>
        <pose>0 0 0 0 -0 0</pose>
        <geometry>
          <mesh>
            <uri>/home/todosi/ar4_ros_driver/install/ar_description/share/ar_description/meshes/ar4/link_4.STL</uri>
            <scale>1 1 1</scale>
          </mesh>
        </geometry>
        <surface>
          <friction>
            <ode>
              <mu>1</mu>
              <mu2>1</mu2>
              <fdir1>0 0 0</fdir1>
              <slip1>0</slip1>
              <slip2>0</slip2>
            </ode>
            <torsional>
              <coefficient>1</coefficient>
              <patch_radius>0</patch_radius>
              <surface_radius>0</surface_radius>
              <use_patch_radius>1</use_patch_radius>
              <ode>
                <slip>0</slip>
              </ode>
            </torsional>
          </friction>
          <bounce>
            <restitution_coefficient>0</restitution_coefficient>
            <threshold>1e+06</threshold>
          </bounce>
          <contact>
            <collide_without_contact>0</collide_without_contact>
            <collide_without_contact_bitmask>1</collide_without_contact_bitmask>
            <collide_bitmask>1</collide_bitmask>
            <ode>
              <soft_cfm>0</soft_cfm>
              <soft_erp>0.2</soft_erp>
              <kp>1e+13</kp>
              <kd>1</kd>
              <max_vel>0.01</max_vel>
              <min_depth>0</min_depth>
            </ode>
            <bullet>
              <split_impulse>1</split_impulse>
              <split_impulse_penetration_threshold>-0.01</split_impulse_penetration_threshold>
              <soft_cfm>0</soft_cfm>
              <soft_erp>0.2</soft_erp>
              <kp>1e+13</kp>
              <kd>1</kd>
            </bullet>
          </contact>
        </surface>
      </collision>
    </link>
    <link name='link_5'>
      <pose>-0.006999 -0.286829 0.474771 1.57079 -0 0</pose>
      <inertial>
        <pose>0.001507 -1.3e-05 -0.012585 0 -0 0</pose>
        <mass>0.11562</mass>
        <inertia>
          <ixx>5.5035e-05</ixx>
          <ixy>-1.019e-08</ixy>
          <ixz>-2.6243e-06</ixz>
          <iyy>8.2921e-05</iyy>
          <iyz>1.4437e-08</iyz>
          <izz>5.2518e-05</izz>
        </inertia>
      </inertial>
      <self_collide>0</self_collide>
      <enable_wind>0</enable_wind>
      <kinematic>0</kinematic>
      <visual name='link_5_visual'>
        <pose>0 0 0 0 -0 0</pose>
        <geometry>
          <mesh>
            <scale>1 1 1</scale>
            <uri>file:///home/todosi/ar4_ros_driver/install/ar_description/share/ar_description/meshes/ar4/link_5.STL</uri>
          </mesh>
        </geometry>
        <material>
          <shader type='pixel'/>
        </material>
        <transparency>0</transparency>
        <cast_shadows>1</cast_shadows>
      </visual>
      <collision name='link_5_collision'>
        <laser_retro>0</laser_retro>
        <max_contacts>10</max_contacts>
        <pose>0 0 0 0 -0 0</pose>
        <geometry>
          <mesh>
            <uri>/home/todosi/ar4_ros_driver/install/ar_description/share/ar_description/meshes/ar4/link_5.STL</uri>
            <scale>1 1 1</scale>
          </mesh>
        </geometry>
        <surface>
          <friction>
            <ode>
              <mu>1</mu>
              <mu2>1</mu2>
              <fdir1>0 0 0</fdir1>
              <slip1>0</slip1>
              <slip2>0</slip2>
            </ode>
            <torsional>
              <coefficient>1</coefficient>
              <patch_radius>0</patch_radius>
              <surface_radius>0</surface_radius>
              <use_patch_radius>1</use_patch_radius>
              <ode>
                <slip>0</slip>
              </ode>
            </torsional>
          </friction>
          <bounce>
            <restitution_coefficient>0</restitution_coefficient>
            <threshold>1e+06</threshold>
          </bounce>
          <contact>
            <collide_without_contact>0</collide_without_contact>
            <collide_without_contact_bitmask>1</collide_without_contact_bitmask>
            <collide_bitmask>1</collide_bitmask>
            <ode>
              <soft_cfm>0</soft_cfm>
              <soft_erp>0.2</soft_erp>
              <kp>1e+13</kp>
              <kd>1</kd>
              <max_vel>0.01</max_vel>
              <min_depth>0</min_depth>
            </ode>
            <bullet>
              <split_impulse>1</split_impulse>
              <split_impulse_penetration_threshold>-0.01</split_impulse_penetration_threshold>
              <soft_cfm>0</soft_cfm>
              <soft_erp>0.2</soft_erp>
              <kp>1e+13</kp>
              <kd>1</kd>
            </bullet>
          </contact>
        </surface>
      </collision>
    </link>
    <link name='link_6'>
      <pose>-0.006999 -0.323079 0.474771 -1.57079 3e-06 -3.14159</pose>
      <inertial>
        <pose>-0.000627 -0.00371 0.021306 0 -0 0</pose>
        <mass>0.093863</mass>
        <inertia>
          <ixx>2.77398e-05</ixx>
          <ixy>-2.07865e-07</ixy>
          <ixz>1.04138e-07</ixz>
          <iyy>4.66684e-05</iyy>
          <iyz>1.03031e-06</iyz>
          <izz>4.34835e-05</izz>
        </inertia>
      </inertial>
      <self_collide>0</self_collide>
      <enable_wind>0</enable_wind>
      <kinematic>0</kinematic>
      <visual name='link_6_visual'>
        <pose>0 0 0 0 -0 0</pose>
        <geometry>
          <mesh>
            <scale>1 1 1</scale>
            <uri>file:///home/todosi/ar4_ros_driver/install/ar_description/share/ar_description/meshes/ar4/link_6.STL</uri>
          </mesh>
        </geometry>
        <material>
          <shader type='pixel'/>
        </material>
        <transparency>0</transparency>
        <cast_shadows>1</cast_shadows>
      </visual>
      <visual name='link_6_fixed_joint_lump__gripper_base_link_visual_1'>
        <pose>0 0 0 -1.5708 0 0</pose>
        <geometry>
          <mesh>
            <scale>1 1 1</scale>
            <uri>file:///home/todosi/ar4_ros_driver/install/ar_description/share/ar_description/meshes/ar4_gripper/gripper_base_link.stl</uri>
          </mesh>
        </geometry>
        <material>
          <shader type='pixel'/>
        </material>
        <transparency>0</transparency>
        <cast_shadows>1</cast_shadows>
      </visual>
      <collision name='link_6_collision'>
        <laser_retro>0</laser_retro>
        <max_contacts>10</max_contacts>
        <pose>0 0 0 0 -0 0</pose>
        <geometry>
          <mesh>
            <uri>/home/todosi/ar4_ros_driver/install/ar_description/share/ar_description/meshes/ar4/link_6.STL</uri>
            <scale>1 1 1</scale>
          </mesh>
        </geometry>
        <surface>
          <friction>
            <ode>
              <mu>1</mu>
              <mu2>1</mu2>
              <fdir1>0 0 0</fdir1>
              <slip1>0</slip1>
              <slip2>0</slip2>
            </ode>
            <torsional>
              <coefficient>1</coefficient>
              <patch_radius>0</patch_radius>
              <surface_radius>0</surface_radius>
              <use_patch_radius>1</use_patch_radius>
              <ode>
                <slip>0</slip>
              </ode>
            </torsional>
          </friction>
          <bounce>
            <restitution_coefficient>0</restitution_coefficient>
            <threshold>1e+06</threshold>
          </bounce>
          <contact>
            <collide_without_contact>0</collide_without_contact>
            <collide_without_contact_bitmask>1</collide_without_contact_bitmask>
            <collide_bitmask>1</collide_bitmask>
            <ode>
              <soft_cfm>0</soft_cfm>
              <soft_erp>0.2</soft_erp>
              <kp>1e+13</kp>
              <kd>1</kd>
              <max_vel>0.01</max_vel>
              <min_depth>0</min_depth>
            </ode>
            <bullet>
              <split_impulse>1</split_impulse>
              <split_impulse_penetration_threshold>-0.01</split_impulse_penetration_threshold>
              <soft_cfm>0</soft_cfm>
              <soft_erp>0.2</soft_erp>
              <kp>1e+13</kp>
              <kd>1</kd>
            </bullet>
          </contact>
        </surface>
      </collision>
      <collision name='link_6_fixed_joint_lump__gripper_base_link_collision_1'>
        <laser_retro>0</laser_retro>
        <max_contacts>10</max_contacts>
        <pose>0 0 0 -1.5708 0 0</pose>
        <geometry>
          <mesh>
            <uri>/home/todosi/ar4_ros_driver/install/ar_description/share/ar_description/meshes/ar4_gripper/gripper_base_link.stl</uri>
            <scale>1 1 1</scale>
          </mesh>
        </geometry>
        <surface>
          <friction>
            <ode>
              <mu>1</mu>
              <mu2>1</mu2>
              <fdir1>0 0 0</fdir1>
              <slip1>0</slip1>
              <slip2>0</slip2>
            </ode>
            <torsional>
              <coefficient>1</coefficient>
              <patch_radius>0</patch_radius>
              <surface_radius>0</surface_radius>
              <use_patch_radius>1</use_patch_radius>
              <ode>
                <slip>0</slip>
              </ode>
            </torsional>
          </friction>
          <bounce>
            <restitution_coefficient>0</restitution_coefficient>
            <threshold>1e+06</threshold>
          </bounce>
          <contact>
            <collide_without_contact>0</collide_without_contact>
            <collide_without_contact_bitmask>1</collide_without_contact_bitmask>
            <collide_bitmask>1</collide_bitmask>
            <ode>
              <soft_cfm>0</soft_cfm>
              <soft_erp>0.2</soft_erp>
              <kp>1e+13</kp>
              <kd>1</kd>
              <max_vel>0.01</max_vel>
              <min_depth>0</min_depth>
            </ode>
            <bullet>
              <split_impulse>1</split_impulse>
              <split_impulse_penetration_threshold>-0.01</split_impulse_penetration_threshold>
              <soft_cfm>0</soft_cfm>
              <soft_erp>0.2</soft_erp>
              <kp>1e+13</kp>
              <kd>1</kd>
            </bullet>
          </contact>
        </surface>
      </collision>
    </link>
    <joint name='gripper_jaw1_joint' type='prismatic'>
      <parent>link_6</parent>
      <child>gripper_jaw1_link</child>
      <pose>0 -0 -0 0 -0 0</pose>
      <axis>
        <xyz>1 0 0</xyz>
        <limit>
          <lower>-0.014</lower>
          <upper>0</upper>
          <effort>0</effort>
          <velocity>0.1</velocity>
        </limit>
        <dynamics>
          <spring_reference>0</spring_reference>
          <spring_stiffness>0</spring_stiffness>
          <damping>0</damping>
          <friction>0</friction>
        </dynamics>
      </axis>
      <physics>
        <ode>
          <limit>
            <cfm>0</cfm>
            <erp>0.2</erp>
          </limit>
          <suspension>
            <cfm>0</cfm>
            <erp>0.2</erp>
          </suspension>
        </ode>
      </physics>
    </joint>
    <joint name='gripper_jaw2_joint' type='prismatic'>
      <parent>link_6</parent>
      <child>gripper_jaw2_link</child>
      <pose>-0 -0 -0 0 -0 0</pose>
      <axis>
        <xyz>1 0 0</xyz>
        <limit>
          <lower>-0.014</lower>
          <upper>0</upper>
          <effort>0</effort>
          <velocity>0.1</velocity>
        </limit>
        <dynamics>
          <spring_reference>0</spring_reference>
          <spring_stiffness>0</spring_stiffness>
          <damping>0</damping>
          <friction>0</friction>
        </dynamics>
      </axis>
      <physics>
        <ode>
          <limit>
            <cfm>0</cfm>
            <erp>0.2</erp>
          </limit>
          <suspension>
            <cfm>0</cfm>
            <erp>0.2</erp>
          </suspension>
        </ode>
      </physics>
    </joint>
    <joint name='joint_1' type='revolute'>
      <parent>base_link</parent>
      <child>link_1</child>
      <pose>0 0 0 0 -0 0</pose>
      <axis>
        <xyz>0 0 1</xyz>
        <limit>
          <lower>-2.96706</lower>
          <upper>2.96706</upper>
          <effort>0</effort>
          <velocity>0.5</velocity>
        </limit>
        <dynamics>
          <spring_reference>0</spring_reference>
          <spring_stiffness>0</spring_stiffness>
          <damping>0</damping>
          <friction>0</friction>
        </dynamics>
      </axis>
      <physics>
        <ode>
          <limit>
            <cfm>0</cfm>
            <erp>0.2</erp>
          </limit>
          <suspension>
            <cfm>0</cfm>
            <erp>0.2</erp>
          </suspension>
        </ode>
      </physics>
    </joint>
    <joint name='joint_2' type='revolute'>
      <parent>link_1</parent>
      <child>link_2</child>
      <pose>-0 -0 0 0 -0 0</pose>
      <axis>
        <xyz>0 0 -1</xyz>
        <limit>
          <lower>-0.733038</lower>
          <upper>1.5708</upper>
          <effort>0.5</effort>
          <velocity>0.5</velocity>
        </limit>
        <dynamics>
          <spring_reference>0</spring_reference>
          <spring_stiffness>0</spring_stiffness>
          <damping>0</damping>
          <friction>0</friction>
        </dynamics>
      </axis>
      <physics>
        <ode>
          <limit>
            <cfm>0</cfm>
            <erp>0.2</erp>
          </limit>
          <suspension>
            <cfm>0</cfm>
            <erp>0.2</erp>
          </suspension>
        </ode>
      </physics>
    </joint>
    <joint name='joint_3' type='revolute'>
      <parent>link_2</parent>
      <child>link_3</child>
      <pose>0 0 0 0 -0 0</pose>
      <axis>
        <xyz>0 0 -1</xyz>
        <limit>
          <lower>-1.55334</lower>
          <upper>0.907571</upper>
          <effort>0</effort>
          <velocity>0.5</velocity>
        </limit>
        <dynamics>
          <spring_reference>0</spring_reference>
          <spring_stiffness>0</spring_stiffness>
          <damping>0</damping>
          <friction>0</friction>
        </dynamics>
      </axis>
      <physics>
        <ode>
          <limit>
            <cfm>0</cfm>
            <erp>0.2</erp>
          </limit>
          <suspension>
            <cfm>0</cfm>
            <erp>0.2</erp>
          </suspension>
        </ode>
      </physics>
    </joint>
    <joint name='joint_4' type='revolute'>
      <parent>link_3</parent>
      <child>link_4</child>
      <pose>0 -0 0 0 -0 0</pose>
      <axis>
        <xyz>0 0 -1</xyz>
        <limit>
          <lower>-2.87979</lower>
          <upper>2.87979</upper>
          <effort>0</effort>
          <velocity>0.5</velocity>
        </limit>
        <dynamics>
          <spring_reference>0</spring_reference>
          <spring_stiffness>0</spring_stiffness>
          <damping>0</damping>
          <friction>0</friction>
        </dynamics>
      </axis>
      <physics>
        <ode>
          <limit>
            <cfm>0</cfm>
            <erp>0.2</erp>
          </limit>
          <suspension>
            <cfm>0</cfm>
            <erp>0.2</erp>
          </suspension>
        </ode>
      </physics>
    </joint>
    <joint name='joint_5' type='revolute'>
      <parent>link_4</parent>
      <child>link_5</child>
      <pose>0 0 0 0 -0 0</pose>
      <axis>
        <xyz>1 0 0</xyz>
        <limit>
          <lower>-1.8326</lower>
          <upper>1.8326</upper>
          <effort>0</effort>
          <velocity>1</velocity>
        </limit>
        <dynamics>
          <spring_reference>0</spring_reference>
          <spring_stiffness>0</spring_stiffness>
          <damping>0</damping>
          <friction>0</friction>
        </dynamics>
      </axis>
      <physics>
        <ode>
          <limit>
            <cfm>0</cfm>
            <erp>0.2</erp>
          </limit>
          <suspension>
            <cfm>0</cfm>
            <erp>0.2</erp>
          </suspension>
        </ode>
      </physics>
    </joint>
    <joint name='joint_6' type='revolute'>
      <parent>link_5</parent>
      <child>link_6</child>
      <pose>-0 0 0 0 -0 0</pose>
      <axis>
        <xyz>0 0 1</xyz>
        <limit>
          <lower>-2.70526</lower>
          <upper>2.70526</upper>
          <effort>0</effort>
          <velocity>1</velocity>
        </limit>
        <dynamics>
          <spring_reference>0</spring_reference>
          <spring_stiffness>0</spring_stiffness>
          <damping>0</damping>
          <friction>0</friction>
        </dynamics>
      </axis>
      <physics>
        <ode>
          <limit>
            <cfm>0</cfm>
            <erp>0.2</erp>
          </limit>
          <suspension>
            <cfm>0</cfm>
            <erp>0.2</erp>
          </suspension>
        </ode>
      </physics>
    </joint>
    <static>0</static>
    <allow_auto_disable>1</allow_auto_disable>
    <plugin name='gazebo_ros2_control' filename='libgazebo_ros2_control.so'>
      <parameters>/home/todosi/ar4_ros_driver/install/ar_hardware_interface/share/ar_hardware_interface/config/controllers.yaml</parameters>
    </plugin>
  </model>
</sdf>
